[2017-07-31 00:13:18,700] [CASS] connecting to cluster
[2017-07-31 00:13:21,017] Using datacenter 'datacenter1' for DCAwareRoundRobinPolicy (via host '127.0.0.1'); if incorrect, please specify a local_dc to the constructor, or limit contact points to local cluster nodes
[2017-07-31 00:13:23,356] [CASS] connecting to auresearch
[2017-07-31 00:13:23,637] [HTTP] starting http server..
[2017-07-31 00:47:19,600] [control connection] Error connecting to 127.0.0.1:
Traceback (most recent call last):
  File "cassandra/cluster.py", line 2648, in cassandra.cluster.ControlConnection._reconnect_internal (cassandra/cluster.c:48590)
    return self._try_connect(host)
  File "cassandra/cluster.py", line 2670, in cassandra.cluster.ControlConnection._try_connect (cassandra/cluster.c:49107)
    connection = self._cluster.connection_factory(host.address, is_control_connection=True)
  File "cassandra/cluster.py", line 1111, in cassandra.cluster.Cluster.connection_factory (cassandra/cluster.c:15331)
    return self.connection_class.factory(address, self.connect_timeout, *args, **kwargs)
  File "cassandra/connection.py", line 324, in cassandra.connection.Connection.factory (cassandra/connection.c:5510)
    conn = cls(host, *args, **kwargs)
  File "/usr/local/lib/python2.7/dist-packages/cassandra/io/asyncorereactor.py", line 299, in __init__
    self._connect_socket()
  File "cassandra/connection.py", line 363, in cassandra.connection.Connection._connect_socket (cassandra/connection.c:6819)
    raise socket.error(sockerr.errno, "Tried connecting to %s. Last error: %s" % ([a[4] for a in addresses], sockerr.strerror or sockerr))
error: [Errno 111] Tried connecting to [('127.0.0.1', 9042)]. Last error: Connection refused
[2017-07-31 00:47:19,601] Heartbeat failed for connection (140594186377616) to 127.0.0.1
[2017-07-31 00:47:19,634] Host 127.0.0.1 has been marked down
[2017-07-31 00:47:20,637] Error attempting to reconnect to 127.0.0.1, scheduling retry in 2.0 seconds: [Errno 111] Tried connecting to [('127.0.0.1', 9042)]. Last error: Connection refused
[2017-07-31 00:47:22,642] Error attempting to reconnect to 127.0.0.1, scheduling retry in 4.0 seconds: [Errno 111] Tried connecting to [('127.0.0.1', 9042)]. Last error: Connection refused

Attaching package: ‘dplyr’

The following objects are masked from ‘package:stats’:

    filter, lag

The following objects are masked from ‘package:base’:

    intersect, setdiff, setequal, union

Map from URL : http://maps.googleapis.com/maps/api/staticmap?center=auburn+university&zoom=12&size=640x640&scale=2&maptype=terrain&language=en-EN&sensor=false
Information from URL : http://maps.googleapis.com/maps/api/geocode/json?address=auburn%20university&sensor=false
null device 
          1 
Map from URL : http://maps.googleapis.com/maps/api/staticmap?center=auburn+university&zoom=14&size=640x640&scale=2&maptype=terrain&language=en-EN&sensor=false
Information from URL : http://maps.googleapis.com/maps/api/geocode/json?address=auburn%20university&sensor=false
